Eventhough I have pandoc and pypandoc inside the container:
"ubuntu@dr-bigdata-aiml-03:/u01/user-data/vint1/meeting_minutes_app$ sudo docker compose ps
NAME                 IMAGE                        COMMAND                  SERVICE   CREATED          STATUS          PORTS
meeting_api_server   meeting_minutes_app-api      "uvicorn app.main:ap…"   api       10 minutes ago   Up 10 minutes   8020/tcp, 8100/tcp, 8501/tcp, 0.0.0.0:8072->8072/tcp, :::8072->8072/tcp
meeting_flower       meeting_minutes_app-flower   "celery -A app.worke…"   flower    10 minutes ago   Up 10 minutes   8020/tcp, 8072/tcp, 8100/tcp, 0.0.0.0:5555->5555/tcp, :::5555->5555/tcp, 8501/tcp
meeting_worker       meeting_minutes_app-worker   "celery -A app.worke…"   worker    10 minutes ago   Up 10 minutes   8020/tcp, 8072/tcp, 8100/tcp, 8501/tcp
ubuntu@dr-bigdata-aiml-03:/u01/user-data/vint1/meeting_minutes_app$ sudo docker exec -it meeting_worker bash
root@49eb59a99343:/code# pip show pandoc
Name: pandoc
Version: 2.4
Summary: Pandoc Documents for Python
Home-page:
Author: Sébastien Boisgérault
Author-email: Sebastien.Boisgerault@minesparis.psl.eu
License: MIT License
Location: /usr/local/lib/python3.12/dist-packages
Requires: plumbum, ply
Required-by:
root@49eb59a99343:/code# pip show pypandoc
Name: pypandoc
Version: 1.15
Summary: Thin wrapper for pandoc.
Home-page: https://github.com/JessicaTegner/pypandoc
Author: b'Juho Veps\xc3\xa4l\xc3\xa4inen'
Author-email: bebraw@gmail.com
License: MIT
Location: /usr/local/lib/python3.12/dist-packages
Requires:
Required-by:
"

There is still eror:
"
================================================================================
===== STEP 2: GENERATING & DOWNLOADING SUMMARIES =====
================================================================================


Testing: POST /summary (type: topic)
  -> [Generate 'topic' Summary] Status: 200
     Response: {
  "request_id": "test_Hop TO 11092025_1759457427",
  "summary_type": "topic",
  "summary_content": "**BIÊN BẢN HỌP TÓM TẮT NỘI DUNG CHÍNH**  \n**Chủ đề:** Chuyển đổi số và quản trị tiến độ các sáng kiến  \n**Loại cuộc họp:** Định kỳ/Chuyên đề  \n**Chủ trì:** Anh Xin  \n**Thành viên tham gia:** Hồ Quang Ngân, các đại diện khối sức hiệp, khối bán lẻ, khố..."
}
Testing: GET /download/document (type: topic)
  -> [Download Document 'topic'] Status: 500
     Response (non-JSON): Internal Server Error...

Testing: POST /summary (type: speaker)
  -> [Generate 'speaker' Summary] Status: 200
     Response: {
  "request_id": "test_Hop TO 11092025_1759457427",
  "summary_type": "speaker",
  "summary_content": "**BIÊN BẢN HỌP TÓM TẮT THEO NGƯỜI NÓI**\n**Chủ đề:** {bbh_name}\n**Loại cuộc họp:** {meeting_type}\n**Chủ trì:** {meeting_host}\n**Thành viên tham gia:** {meeting_members_str}\n-------------------------------------------\n\n### F - M\n- Báo cáo tổng quan về ..."
}
Testing: GET /download/document (type: speaker)
  -> [Download Document 'speaker'] Status: 500
     Response (non-JSON): Internal Server Error...

Testing: POST /summary (type: summary_bbh_hdqt)
  -> [Generate 'summary_bbh_hdqt' Summary] Status: 502
     Response: {
  "detail": "Failed to get response from AI service: An unexpected error occurred: '\\n  \"start_time\"'"
}
Testing: GET /download/document (type: summary_bbh_hdqt)
  -> [Download Document 'summary_bbh_hdqt'] Status: 502
     Response: {
  "detail": "Failed to get response from AI service: An unexpected error occurred: '\\n  \"start_time\"'"
}

Testing: POST /summary (type: summary_nghi_quyet)
  -> [Generate 'summary_nghi_quyet' Summary] Status: 502
     Response: {
  "detail": "Failed to get response from AI service: An unexpected error occurred: '\\n  \"ngay\"'"
}
Testing: GET /download/document (type: summary_nghi_quyet)
  -> [Download Document 'summary_nghi_quyet'] Status: 502
     Response: {
  "detail": "Failed to get response from AI service: An unexpected error occurred: '\\n  \"ngay\"'"
}


Verifying that the summary edit was saved permanently...
  -> FAILURE: The edited summary content was not found.
  -> [Verify Saved Edit] Status: 200
     Response: {
  "request_id": "test_Hop TO 11092025_1759457427",
  "summary_type": "topic",
  "summary_content": "**BIÊN BẢN HỌP TÓM TẮT NỘI DUNG CHÍNH**  \n**Chủ đề:** Chuyển đổi số và quản trị tiến độ các sáng kiến  \n**Loại cuộc họp:** Định kỳ/Chuyên đề  \n**Chủ trì:** Anh Xin  \n**Thành viên tham gia:** Hồ Quang Ngân, các đại diện khối sức hiệp, khối bán lẻ, khố..."
}

"
this is the log:
"
meeting_api_server  | 2025-10-03 09:11:42,320 - INFO - pypandoc - See http://johnmacfarlane.net/pandoc/installing.html
meeting_api_server  | for installation options
meeting_api_server  |
meeting_api_server  | [INFO] ---------------------------------------------------------------
meeting_api_server  |
meeting_api_server  |
meeting_api_server  | 2025-10-03 09:11:42,320 - INFO - pypandoc - ---------------------------------------------------------------
meeting_api_server  |
meeting_api_server  |
meeting_api_server  | 2025-10-03 09:11:42,320 - WARNING - app.services.document_generator - Pandoc conversion failed: No pandoc was found: either install pandoc and add it
meeting_api_server  | to your PATH or or call pypandoc.download_pandoc(...) or
meeting_api_server  | install pypandoc wheels with included pandoc.. Falling back to custom parser.
meeting_api_server  | 2025-10-03 09:11:42,401 INFO sqlalchemy.engine.Engine ROLLBACK
meeting_api_server  | 2025-10-03 09:11:42,401 - INFO - sqlalchemy.engine.Engine - ROLLBACK
meeting_api_server  | INFO:     172.26.0.5:39198 - "GET /api/v1/meeting/test_Hop%20TO%2011092025_1759457427/download/document?username=test_user_01&summary_type=speaker HTTP/1.1" 500 Internal Server Error
meeting_api_server  | ERROR:    Exception in ASGI application
meeting_api_server  | Traceback (most recent call last):
meeting_api_server  |   File "/usr/local/lib/python3.12/dist-packages/uvicorn/protocols/http/httptools_impl.py", line 409, in run_asgi
meeting_api_server  |     result = await app(  # type: ignore[func-returns-value]
meeting_api_server  |              ^^^^^^^^^^^^^^^^^^^^^^^^^^^^^^^^^^^^^^^^^^^^^^
meeting_api_server  |   File "/usr/local/lib/python3.12/dist-packages/uvicorn/middleware/proxy_headers.py", line 60, in __call__
meeting_api_server  |     return await self.app(scope, receive, send)
meeting_api_server  |            ^^^^^^^^^^^^^^^^^^^^^^^^^^^^^^^^^^^^
meeting_api_server  |   File "/usr/local/lib/python3.12/dist-packages/fastapi/applications.py", line 1054, in __call__
meeting_api_server  |     await super().__call__(scope, receive, send)
meeting_api_server  |   File "/usr/local/lib/python3.12/dist-packages/starlette/applications.py", line 112, in __call__
meeting_api_server  |     await self.middleware_stack(scope, receive, send)
meeting_api_server  |   File "/usr/local/lib/python3.12/dist-packages/starlette/middleware/errors.py", line 187, in __call__
meeting_api_server  |     raise exc
meeting_api_server  |   File "/usr/local/lib/python3.12/dist-packages/starlette/middleware/errors.py", line 165, in __call__
meeting_api_server  |     await self.app(scope, receive, _send)
meeting_api_server  |   File "/usr/local/lib/python3.12/dist-packages/starlette/middleware/cors.py", line 85, in __call__
meeting_api_server  |     await self.app(scope, receive, send)
meeting_api_server  |   File "/usr/local/lib/python3.12/dist-packages/starlette/middleware/exceptions.py", line 62, in __call__
meeting_api_server  |     await wrap_app_handling_exceptions(self.app, conn)(scope, receive, send)
meeting_api_server  |   File "/usr/local/lib/python3.12/dist-packages/starlette/_exception_handler.py", line 53, in wrapped_app
meeting_api_server  |     raise exc
meeting_api_server  |   File "/usr/local/lib/python3.12/dist-packages/starlette/_exception_handler.py", line 42, in wrapped_app
meeting_api_server  |     await app(scope, receive, sender)
meeting_api_server  |   File "/usr/local/lib/python3.12/dist-packages/starlette/routing.py", line 714, in __call__
meeting_api_server  |     await self.middleware_stack(scope, receive, send)
meeting_api_server  |   File "/usr/local/lib/python3.12/dist-packages/starlette/routing.py", line 734, in app
meeting_api_server  |     await route.handle(scope, receive, send)
meeting_api_server  |   File "/usr/local/lib/python3.12/dist-packages/starlette/routing.py", line 288, in handle
meeting_api_server  |     await self.app(scope, receive, send)
meeting_api_server  |   File "/usr/local/lib/python3.12/dist-packages/starlette/routing.py", line 76, in app
meeting_api_server  |     await wrap_app_handling_exceptions(app, request)(scope, receive, send)
meeting_api_server  |   File "/usr/local/lib/python3.12/dist-packages/starlette/_exception_handler.py", line 53, in wrapped_app
meeting_api_server  |     raise exc
meeting_api_server  |   File "/usr/local/lib/python3.12/dist-packages/starlette/_exception_handler.py", line 42, in wrapped_app
meeting_api_server  |     await app(scope, receive, sender)
meeting_api_server  |   File "/usr/local/lib/python3.12/dist-packages/starlette/routing.py", line 73, in app
meeting_api_server  |     response = await f(request)
meeting_api_server  |                ^^^^^^^^^^^^^^^^
meeting_api_server  |   File "/usr/local/lib/python3.12/dist-packages/fastapi/routing.py", line 301, in app
meeting_api_server  |     raw_response = await run_endpoint_function(
meeting_api_server  |                    ^^^^^^^^^^^^^^^^^^^^^^^^^^^^
meeting_api_server  |   File "/usr/local/lib/python3.12/dist-packages/fastapi/routing.py", line 212, in run_endpoint_function
meeting_api_server  |     return await dependant.call(**values)
meeting_api_server  |            ^^^^^^^^^^^^^^^^^^^^^^^^^^^^^^
meeting_api_server  |   File "/code/app/api/routes/meeting.py", line 735, in download_summary_document
meeting_api_server  |     return StreamingResponse(
meeting_api_server  |            ^^^^^^^^^^^^^^^^^^
meeting_api_server  |   File "/usr/local/lib/python3.12/dist-packages/starlette/responses.py", line 230, in __init__
meeting_api_server  |     self.init_headers(headers)
meeting_api_server  |   File "/usr/local/lib/python3.12/dist-packages/starlette/responses.py", line 61, in init_headers
meeting_api_server  |     raw_headers = [(k.lower().encode("latin-1"), v.encode("latin-1")) for k, v in headers.items()]
meeting_api_server  |                                                  ^^^^^^^^^^^^^^^^^^^
meeting_api_server  | UnicodeEncodeError: 'latin-1' codec can't encode character '\u1ed9' in position 39: ordinal not in range(256)


meeting_api_server  | WHERE transcription.meeting_job_id = %(meeting_job_id_1)s AND transcription.language = %(language_1)s
meeting_api_server  | 2025-10-03 09:11:43,459 INFO sqlalchemy.engine.Engine [cached since 25.23s ago] {'meeting_job_id_1': 9, 'language_1': 'vi'}
meeting_api_server  | 2025-10-03 09:11:43,459 - INFO - sqlalchemy.engine.Engine - [cached since 25.23s ago] {'meeting_job_id_1': 9, 'language_1': 'vi'}
meeting_api_server  | 2025-10-03 09:11:43,469 - ERROR - app.services.ai_service - An unexpected error occurred in AIService for task 'summary_bbh_hdqt': '\n  "start_time"'
meeting_api_server  | Traceback (most recent call last):
meeting_api_server  |   File "/code/app/services/ai_service.py", line 87, in get_response
meeting_api_server  |     system_prompt = system_prompt.format(**context["meeting_info"])
meeting_api_server  |                     ^^^^^^^^^^^^^^^^^^^^^^^^^^^
"
