
During handling of the above exception, another exception occurred:

Traceback (most recent call last):
  File "/test_client/test_api.py", line 207, in <module>
    run_full_test()
  File "/test_client/test_api.py", line 101, in run_full_test
    response = requests.post(f"{API_BASE_URL}/speaker/", data=payload, files=files_to_upload)
  File "/usr/local/lib/python3.9/site-packages/requests/api.py", line 115, in post
    return request("post", url, data=data, json=json, **kwargs)
  File "/usr/local/lib/python3.9/site-packages/requests/api.py", line 59, in request
    return session.request(method=method, url=url, **kwargs)
  File "/usr/local/lib/python3.9/site-packages/requests/sessions.py", line 589, in request
    resp = self.send(prep, **send_kwargs)
  File "/usr/local/lib/python3.9/site-packages/requests/sessions.py", line 703, in send
    r = adapter.send(request, **kwargs)
  File "/usr/local/lib/python3.9/site-packages/requests/adapters.py", line 677, in send
    raise ConnectionError(e, request=request)
requests.exceptions.ConnectionError: HTTPConnectionPool(host='api', port=8072): Max retries exceeded with url: /api/v1/speaker/ (Caused by NewConnectionError('<urllib3.connection.HTTPConnection object at 0x7faa9654bd60>: Failed to establish a new connection: [Errno 111] Connection refused'))
root@818b610315f7:/test_client# ^C
