@818b610315f7:/test_client# ^C
root@818b610315f7:/test_client# python3 test_api.py
Loaded metadata for 7 speakers.
Found 2 meetings to process.

--- STEP 1: ENROLLING SPEAKERS ---
Enrolling speaker 'TAKEOS' with 0 samples...
  -> Status: 422, Response: {'detail': [{'type': 'missing', 'loc': ['body', 'files'], 'msg': 'Field required', 'input': None}]}
Enrolling speaker 'BINHTM' with 159 samples...
Traceback (most recent call last):
  File "/usr/local/lib/python3.9/site-packages/requests/models.py", line 976, in json
    return complexjson.loads(self.text, **kwargs)
  File "/usr/local/lib/python3.9/json/__init__.py", line 346, in loads
    return _default_decoder.decode(s)
  File "/usr/local/lib/python3.9/json/decoder.py", line 337, in decode
    obj, end = self.raw_decode(s, idx=_w(s, 0).end())
  File "/usr/local/lib/python3.9/json/decoder.py", line 355, in raw_decode
    raise JSONDecodeError("Expecting value", s, err.value) from None
json.decoder.JSONDecodeError: Expecting value: line 1 column 1 (char 0)

During handling of the above exception, another exception occurred:

Traceback (most recent call last):
  File "/test_client/test_api.py", line 204, in <module>
    run_full_test()
  File "/test_client/test_api.py", line 99, in run_full_test
    print(f"  -> Status: {response.status_code}, Response: {response.json()}")
  File "/usr/local/lib/python3.9/site-packages/requests/models.py", line 980, in json
    raise RequestsJSONDecodeError(e.msg, e.doc, e.pos)
